Workbook

Sheet Variables
A1: Month | B1: Week | C1: Year | D1: Outreachs | E1: Scheduled 1:1 | F1: Scheduling rate | G1: No show | H1: 1:1 rate | I1: Deals | J1: Deal rate
A2: October | B2: 40 | C2: 2025 | D2: =COUNTIFS('2025.10'!I:I,">="&DATE(2025,10,1),'2025.10'!I:I,"<="&DATE(2025,10,3)) -> 354 | E2: =COUNTIFS('2025.10'!I:I,">="&DATE(2025,10,1),'2025.10'!I:I,"<="&DATE(2025,10,3), '2025.10'!L:L, "Call Done")+G2 -> 25 | F2: =E2/D2 -> 0.070621469 | G2: =COUNTIFS('2025.10'!I:I,">="&DATE(2025,10,1),'2025.10'!I:I,"<="&DATE(2025,10,3), '2025.10'!L:L, "No show") -> 13 | H2: =(E2-G2)/E2 -> 0.48 | I2: 0 | J2: =I2/E2 -> 0
A3: October | B3: 41 | C3: 2025 | D3: =COUNTIFS('2025.10'!I:I,">="&DATE(2025,10,6),'2025.10'!I:I,"<="&DATE(2025,10,10)) -> 557 | E3: =COUNTIFS('2025.10'!I:I,">="&DATE(2025,10,6),'2025.10'!I:I,"<="&DATE(2025,10,10), '2025.10'!L:L, "Call Done")+G3 -> 43 | F3: =E3/D3 -> 0.077199282 | G3: =COUNTIFS('2025.10'!I:I,">="&DATE(2025,10,6),'2025.10'!I:I,"<="&DATE(2025,10,10), '2025.10'!L:L, "No show") -> 20 | H3: =(E3-G3)/E3 -> 0.53488372 | I3: 0 | J3: =I3/E3 -> 0
A4: October | B4: 42 | C4: 2025 | D4: =COUNTIFS('2025.10'!I:I,">="&DATE(2025,10,13),'2025.10'!I:I,"<="&DATE(2025,10,17)) -> 454 | E4: =COUNTIFS('2025.10'!I:I,">="&DATE(2025,10,13),'2025.10'!I:I,"<="&DATE(2025,10,17), '2025.10'!L:L, "Call Done")+G4 -> 15 | F4: =E4/D4 -> 0.033039648 | G4: =COUNTIFS('2025.10'!I:I,">="&DATE(2025,10,13),'2025.10'!I:I,"<="&DATE(2025,10,17), '2025.10'!L:L, "No show") -> 10 | H4: =(E4-G4)/E4 -> 0.33333333 | I4: 0 | J4: =I4/E4 -> 0
A5: October | B5: 43 | C5: 2025 | D5: =COUNTIFS('2025.10'!I:I,">="&DATE(2025,10,20),'2025.10'!I:I,"<="&DATE(2025,10,24)) -> 183 | E5: =COUNTIFS('2025.10'!I:I,">="&DATE(2025,10,20),'2025.10'!I:I,"<="&DATE(2025,10,24),'2025.10'!L:L, "Call Done")+G5 -> 12 | F5: =E5/D5 -> 0.06557377 | G5: =COUNTIFS('2025.10'!I:I,">="&DATE(2025,10,20),'2025.10'!I:I,"<="&DATE(2025,10,24),'2025.10'!L:L, "No show") -> 3 | H5: =(E5-G5)/E5 -> 0.75 | I5: 0 | J5: =I5/E5 -> 0
A6: October | B6: 44 | C6: 2025 | D6: =COUNTIFS('2025.10'!I:I,">="&DATE(2025,10,27),'2025.10'!I:I,"<="&DATE(2025,10,31)) -> 476 | E6: =COUNTIFS('2025.10'!I:I,">="&DATE(2025,10,27),'2025.10'!I:I,"<="&DATE(2025,10,31), '2025.10'!L:L, "Call Done")+G6 -> 17 | F6: =E6/D6 -> 0.035714286 | G6: =COUNTIFS('2025.10'!I:I,">="&DATE(2025,10,27),'2025.10'!I:I,"<="&DATE(2025,10,31), '2025.10'!L:L, "No show") -> 8 | H6: =(E6-G6)/E6 -> 0.52941176 | I6: 0 | J6: =I6/E6 -> 0
A7: November | B7: 45 | C7: 2025 | D7: =COUNTIFS('2025.11'!I:I,">="&DATE(2025,11,3),'2025.11'!I:I,"<="&DATE(2025,11,7)) -> 303 | E7: =COUNTIFS('2025.11'!I:I,">="&DATE(2025,11,3),'2025.11'!I:I,"<="&DATE(2025,11,7), '2025.11'!L:L, "Call Done")+G7 -> 13 | F7: =E7/D7 -> 0.04290429 | G7: =COUNTIFS('2025.11'!I:I,">="&DATE(2025,11,3),'2025.11'!I:I,"<="&DATE(2025,11,7), '2025.11'!L:L, "No show") -> 8 | H7: =(E7-G7)/E7 -> 0.38461538 | I7: 0 | J7: =I7/E7 -> 0
A8: November | B8: 46 | C8: 2025 | D8: =COUNTIFS('2025.11'!I:I,">="&DATE(2025,11,10),'2025.11'!I:I,"<="&DATE(2025,11,14)) -> 475 | E8: =COUNTIFS('2025.11'!I:I,">="&DATE(2025,11,10),'2025.11'!I:I,"<="&DATE(2025,11,14), '2025.11'!L:L, "Call Done")+G8 -> 3 | F8: =E8/D8 -> 0.0063157895 | G8: =COUNTIFS('2025.11'!I:I,">="&DATE(2025,11,10),'2025.11'!I:I,"<="&DATE(2025,11,14), '2025.11'!L:L, "No show") -> 1 | H8: =(E8-G8)/E8 -> 0.66666667 | I8: 0 | J8: =I8/E8 -> 0
A9: November | B9: 47 | C9: 2025
A10: November | B10: 48 | C10: 2025
C11: 2025
C12: 2025
C13: 2025
C14: 2025
C15: 2025

Sheet 2025.10
C6: BNI Chapter | D6: Address | E6: Member Name | F6: Company | G6: Profession | H6: Phone | I6: Contact | J6: Sales Executive | K6: SDR | L6: Status
C7: BNI Vision | D7: Kendall, FL, 33173 | E7: Alejandro Jordan | F7: ESQ.title | Real Estate Law | G7: Real Estate Law | H7: 305-606-3855 | I7: =DATE(2025, 10, 1) -> 45931 | J7: Gabriel Khalil | K7: Gabriel Khalil
C8: BNI Vision | D8: Kendall, FL, 33174 | E8: Angel F. Fernandez | F8: Fernandez-Bergnes & Assoc PA | G8: Tax Advisor | H8: 305-648-7100 | I8: =DATE(2025, 10, 1) -> 45931 | J8: Gabriel Khalil | K8: Gabriel Khalil
C9: BNI Vision | D9: Kendall, FL, 33175 | E9: Christina Geeza | F9: Corporate Attorney | G9: Company Formation | H9: 3055679000 | I9: =DATE(2025, 10, 1) -> 45931 | J9: Gabriel Khalil | K9: Gabriel Khalil
C10: BNI Vision | D10: Kendall, FL, 33176 | E10: Christopher Gabriel | F10: Smart Business Solutions Consultation Corp | G10: IT Consultants | H10: 3055030873 | I10: =DATE(2025, 10, 1) -> 45931 | J10: Gabriel Khalil | K10: Gabriel Khalil
C11: BNI Vision | D11: Kendall, FL, 33177 | E11: Dmitriy Smirnov | F11: Top Lead marketing | G11: Web Design | H11: 941-350-2656 | I11: =DATE(2025, 10, 1) -> 45931 | J11: Gabriel Khalil | K11: Gabriel Khalil
C12: BNI Vision | D12: Kendall, FL, 33178 | E12: Elisabeth Leyva Fernandez | F12: Leyva Law Office P.A. | G12: Family Law | H12: 3059652452 | I12: =DATE(2025, 10, 1) -> 45931 | J12: Gabriel Khalil | K12: Gabriel Khalil
C13: BNI Vision | D13: Kendall, FL, 33179 | E13: Gabriela Dominguez | F13: Avante Insurance Agency Inc. | G13: Property & Casualty Insurance | H13: 305-812-7605 | I13: =DATE(2025, 10, 1) -> 45931 | J13: Gabriel Khalil | K13: Gabriel Khalil
C14: BNI Vision | D14: Kendall, FL, 33180 | E14: Gina Chevallier | F14: LAW OFFICE OF GINA R. CHEVALLIER | G14: Estate Planning Law | H14: (305) 974-1490 | I14: =DATE(2025, 10, 1) -> 45931 | J14: Gabriel Khalil | K14: Gabriel Khalil
C15: BNI Vision | D15: Kendall, FL, 33181 | E15: Leodan Leonel Leon Naranjo | F15: BERKSHIRE HATHAWAY | G15: Residential Real Estate Agent | H15: 7869052481 | I15: =DATE(2025, 10, 1) -> 45931 | J15: Gabriel Khalil | K15: Gabriel Khalil
C16: BNI Vision | D16: Kendall, FL, 33182 | E16: Mario Louis | F16: Law Offices of M.J. Louis P.A. | G16: Personal Injury Law | H16: 305-377-9646 | I16: =DATE(2025, 10, 1) -> 45931 | J16: Gabriel Khalil | K16: Gabriel Khalil
C17: BNI Vision | D17: Kendall, FL, 33183 | E17: Raul Isern | F17: Atlantic Family Wealth | G17: Financial Advisor | H17: 305-222-0977 | I17: =DATE(2025, 10, 1) -> 45931 | J17: Gabriel Khalil | K17: Gabriel Khalil
C18: BNI Vision | D18: Kendall, FL, 33184 | E18: Simone Da Silva | F18: Bright Lighthouse Insurance | G18: Health Insurance | H18: 7862771870 | I18: =DATE(2025, 10, 1) -> 45931 | J18: Gabriel Khalil | K18: Gabriel Khalil
C19: BNI Connectify | D19: West Kendall, FL, 33185 | E19: Abraham Valera | F19: Reliable Choice Insurance | G19: Property & Casualty Insurance | H19: 305 299 4155 | I19: =DATE(2025, 10, 1) -> 45931 | J19: Gabriel Khalil | K19: Gabriel Khalil | L19: Out of pipe
C20: BNI Connectify | D20: West Kendall, FL, 33186 | E20: Ashley Brosky | F20: Luxe Properties | G20: Residential Real Estate Agent | H20: 305-788-3720 | I20: =DATE(2025, 10, 1) -> 45931 | J20: Gabriel Khalil | K20: Gabriel Khalil
C21: BNI Connectify | D21: West Kendall, FL, 33187 | E21: Barbara Rancano | F21: AirCool Florida | G21: HVAC - Heating & Air | H21: 305-254-8330 | I21: =DATE(2025, 10, 1) -> 45931 | J21: Gabriel Khalil | K21: Gabriel Khalil | L21: No show
C22: BNI Connectify | D22: West Kendall, FL, 33188 | E22: Darren Price | F22: Affix Handyman Solutions LLC | G22: Handyman | H22: 7862233003 | I22: =DATE(2025, 10, 1) -> 45931 | J22: Gabriel Khalil | K22: Gabriel Khalil | L22: Out of pipe
C23: BNI Connectify | D23: West Kendall, FL, 33189 | E23: Hope Khan | F23: The Closing Table of Florida | G23: Title Services | H23: 7865426287 | I23: =DATE(2025, 10, 1) -> 45931 | J23: Gabriel Khalil | K23: Gabriel Khalil
C24: BNI Connectify | D24: West Kendall, FL, 33190 | E24: Joseph Morana | F24: Paw-Fect Home Inspections | G24: Home Inspection | H24: 786-702-9160 | I24: =DATE(2025, 10, 1) -> 45931 | J24: Gabriel Khalil | K24: Gabriel Khalil
C25: BNI Connectify | D25: West Kendall, FL, 33191 | E25: Juan Ignacio Caffini | F25: HandyPro - South Miami | G25: Builder/General Contractor | H25: 786 205 8961 | I25: =DATE(2025, 10, 1) -> 45931 | J25: Gabriel Khalil | K25: Gabriel Khalil | L25: No show
C26: BNI Connectify | D26: West Kendall, FL, 33192 | E26: Michael Moreira | F26: Warrior Law Group | G26: Personal Injury Law | H26: 13059169123 | I26: =DATE(2025, 10, 1) -> 45931 | J26: Gabriel Khalil | K26: Gabriel Khalil
C27: BNI Connectify | D27: West Kendall, FL, 33193 | E27: Nicholas Iglesias | F27: Dade Mortgage Solutions LLC | G27: Residential Mortgages | H27: 3053904382 | I27: =DATE(2025, 10, 1) -> 45931 | J27: Gabriel Khalil | K27: Gabriel Khalil
C28: BNI Connectify | D28: West Kendall, FL, 33194 | E28: Shaun Judy | F28: Dade Pest Solutions | G28: Pest Control | H28: 3053305565 | I28: =DATE(2025, 10, 1) -> 45931 | J28: Gabriel Khalil | K28: Gabriel Khalil
C29: BNI Connectify | D29: West Kendall, FL, 33195 | E29: Stephanie Acevedo | F29: Stellar Public Adjusting Services | G29: Insurance Adjuster | H29: 17862538975 | I29: =DATE(2025, 10, 1) -> 45931 | J29: Gabriel Khalil | K29: Gabriel Khalil | L29: On hold
C30: BNI Virtual Success | D30: Pinecrest, FL, 33156 | E30: Alejandro Velez | F30: VIA Lawyers | G30: Business Law | H30: 3054251565 | I30: =DATE(2025, 10, 1) -> 45931 | J30: Gabriel Khalil | K30: Gabriel Khalil
C31: BNI Virtual Success | D31: Pinecrest, FL, 33157 | E31: Jason Wright | F31: PS Lending | G31: Residential Mortgages | H31: 7862106388 | I31: =DATE(2025, 10, 1) -> 45931 | J31: Gabriel Khalil | K31: Gabriel Khalil | L31: Call Done
C32: BNI Virtual Success | D32: Pinecrest, FL, 33158 | E32: Joey Joseph | F32: Dohan CPA | G32: Certified Public Accountant (CPA) | H32: 3059267315 | I32: =DATE(2025, 10, 1) -> 45931 | J32: Gabriel Khalil | K32: Gabriel Khalil
C33: BNI Virtual Success | D33: Pinecrest, FL, 33159 | E33: Justine Ochoa | F33: IHT Wealth Management | G33: Financial Advisor | H33: 3123341336 | I33: =DATE(2025, 10, 1) -> 45931 | J33: Gabriel Khalil | K33: Gabriel Khalil
C34: BNI Virtual Success | D34: Pinecrest, FL, 33160 | E34: Karla Jaimes | F34: EXP Realty | G34: Residential Real Estate Agent | H34: 9413506909 | I34: =DATE(2025, 10, 1) -> 45931 | J34: Gabriel Khalil | K34: Gabriel Khalil
C35: BNI Virtual Success | D35: Pinecrest, FL, 33161 | E35: Katie FitzGerald | F35: KFitz Consulting | G35: Marketing Consultant | H35: (786) 338-8058 | I35: =DATE(2025, 10, 1) -> 45931 | J35: Gabriel Khalil | K35: Gabriel Khalil
C36: BNI Virtual Success | D36: Pinecrest, FL, 33162 | E36: Michael Garcia | F36: RESF | G36: Commercial Real Estate | H36: 3052508297 | I36: =DATE(2025, 10, 1) -> 45931 | J36: Gabriel Khalil | K36: Gabriel Khalil
C37: BNI Virtual Success | D37: Pinecrest, FL, 33163 | E37: Ricardo Alonso | F37: Atesa Risk Advisors | G37: Property & Casualty Insurance | H37: 3055014845 | I37: =DATE(2025, 10, 1) -> 45931 | J37: Gabriel Khalil | K37: Gabriel Khalil
C38: BNI Virtual Success | D38: Pinecrest, FL, 33164 | E38: Roberto Fernandez | F38: Dania S. Fernandez and Associates P.A. | G38: Real Estate Law | H38: 7868977461 | I38: =DATE(2025, 10, 1) -> 45931 | J38: Gabriel Khalil | K38: Gabriel Khalil
C39: BNI Virtual Success | D39: Pinecrest, FL, 33165 | E39: Tatiana Cardoso | F39: N/A | G39: Personal Injury Law | H39: 7864129511 | I39: =DATE(2025, 10, 1) -> 45931 | J39: Gabriel Khalil | K39: Gabriel Khalil
C40: BNI Virtual Success | D40: Pinecrest, FL, 33166 | E40: Victor Castillo | F40: Castle Inspections | G40: Home Inspection | H40: 786-340-1500 | I40: =DATE(2025, 10, 1) -> 45931 | J40: Gabriel Khalil | K40: Gabriel Khalil
C41: BNI Virtual Success | D41: Pinecrest, FL, 33167 | E41: Will Bradwell | F41: Dade Local | G41: Print Advertising | H41: 7864578993 | I41: =DATE(2025, 10, 1) -> 45931 | J41: Gabriel Khalil | K41: Gabriel Khalil
C42: BNI Business Hub | D42: Pinecrest, FL, 33156 | E42: Agatha Landaetta | F42: The Key To Insurance, LLC | G42: Property & Casualty Insurance | H42: 7864614880 | I42: =DATE(2025, 10, 1) -> 45931 | J42: Gabriel Khalil | K42: Gabriel Khalil | L42: No show
C43: BNI Business Hub | D43: Pinecrest, FL, 33157 | E43: Alejandro Benavides | F43: HomeTeam | G43: Home Inspection | H43: 3057982085 | I43: =DATE(2025, 10, 1) -> 45931 | J43: Gabriel Khalil | K43: Gabriel Khalil
C44: BNI Business Hub | D44: Pinecrest, FL, 33158 | E44: Alex Martinez | F44: Alex A Martínez PA | G44: Estate Planning Law | H44: 3053799600 | I44: =DATE(2025, 10, 1) -> 45931 | J44: Gabriel Khalil | K44: Gabriel Khalil
C45: BNI Business Hub | D45: Pinecrest, FL, 33159 | E45: Arseni Kusakin | F45: Aigen Injury Law | G45: Personal Injury Law | H45: 19173404037 | I45: =DATE(2025, 10, 1) -> 45931 | J45: Gabriel Khalil | K45: Gabriel Khalil
...

Sheet 2025.11
C6: BNI Chapter | D6: Address | E6: Member Name | F6: Company | G6: Profession | H6: Phone | I6: Contact | J6: Sales Executive | K6: SDR | L6: Status
C7: BNI Doral en Espanol | D7: Doral Contemporary Art Museum, 3450 NW 83rd Avenue, Ste 216, Doral Florida, 33166 | E7: Ana Navarro | F7: Algoritmo Agency | G7: Advertising & Marketing > Digital Marketing | H7: +17868219725 | I7: =DATE(2025, 11, 3) -> 45964 | J7: Gabriel Khalil | K7: Jonathan Oliveira
C8: BNI Doral en Espanol | D8: Doral Contemporary Art Museum, 3450 NW 83rd Avenue, Ste 216, Doral Florida, 33167 | E8: Analay Pena del Sol | F8: N/A | G8: Finance & Insurance > Insurance Adjuster | H8: 9546675939 | I8: =DATE(2025, 11, 3) -> 45964 | J8: Gabriel Khalil | K8: Jonathan Oliveira
C9: BNI Doral en Espanol | D9: Doral Contemporary Art Museum, 3450 NW 83rd Avenue, Ste 216, Doral Florida, 33168 | E9: Antonio Petruzzi | F9: Your Financial Team | G9: Finance & Insurance > Mutual Funds | H9: 3055907799 | I9: =DATE(2025, 11, 3) -> 45964 | J9: Gabriel Khalil | K9: Jonathan Oliveira
C10: BNI Doral en Espanol | D10: Doral Contemporary Art Museum, 3450 NW 83rd Avenue, Ste 216, Doral Florida, 33169 | E10: Christian Ramirez | F10: Top Tier Restoration Services | G10: Construction > Restoration | H10: 7865470307 | I10: =DATE(2025, 11, 3) -> 45964 | J10: Gabriel Khalil | K10: Jonathan Oliveira
C11: BNI Doral en Espanol | D11: Doral Contemporary Art Museum, 3450 NW 83rd Avenue, Ste 216, Doral Florida, 33170 | E11: Diana Mazud | F11: N/A | G11: Finance & Insurance > Residential Mortgages | H11: 7862874958 | I11: =DATE(2025, 11, 3) -> 45964 | J11: Gabriel Khalil | K11: Jonathan Oliveira
C12: BNI Doral en Espanol | D12: Doral Contemporary Art Museum, 3450 NW 83rd Avenue, Ste 216, Doral Florida, 33171 | E12: Elsa de Lemos | F12: Bambi International Foundation | G12: Organizations & Others > Non-Profits/Fundraising Organizations | H12: 4076831434 | I12: =DATE(2025, 11, 3) -> 45964 | J12: Gabriel Khalil | K12: Jonathan Oliveira
C13: BNI Doral en Espanol | D13: Doral Contemporary Art Museum, 3450 NW 83rd Avenue, Ste 216, Doral Florida, 33172 | E13: Elwin Manjarres | F13: Emet International Insurance LLC | G13: Finance & Insurance > Commercial Insurance | H13: 786-6140217 | I13: =DATE(2025, 11, 3) -> 45964 | J13: Gabriel Khalil | K13: Jonathan Oliveira | L13: Call Done
C14: BNI Doral en Espanol | D14: Doral Contemporary Art Museum, 3450 NW 83rd Avenue, Ste 216, Doral Florida, 33173 | E14: EUFRACIO GELVES | F14: Elite International Consultants Inc | G14: Finance & Insurance > Life and Disability Insurance | H14: 3053785210 | I14: =DATE(2025, 11, 3) -> 45964 | J14: Gabriel Khalil | K14: Jonathan Oliveira
C15: BNI Doral en Espanol | D15: Doral Contemporary Art Museum, 3450 NW 83rd Avenue, Ste 216, Doral Florida, 33174 | E15: Fayra Holguin | F15: Nexus R&C Llc | G15: Architecture & Engineering > Architecture & Engineering (Other) | H15: 7866517640 | I15: =DATE(2025, 11, 3) -> 45964 | J15: Gabriel Khalil | K15: Jonathan Oliveira
C16: BNI Doral en Espanol | D16: Doral Contemporary Art Museum, 3450 NW 83rd Avenue, Ste 216, Doral Florida, 33175 | E16: Francisco Hernadez | F16: Dr.Be | G16: Health & Wellness > Chiropractor | H16: +17864938102 | I16: =DATE(2025, 11, 3) -> 45964 | J16: Gabriel Khalil | K16: Jonathan Oliveira
C17: BNI Doral en Espanol | D17: Doral Contemporary Art Museum, 3450 NW 83rd Avenue, Ste 216, Doral Florida, 33176 | E17: Giselle Oviedo | F17: KUNAK USA LLC | G17: Computer & Programming > IT & Networks | H17: +13057732718 | I17: =DATE(2025, 11, 3) -> 45964 | J17: Gabriel Khalil | K17: Jonathan Oliveira
C18: BNI Doral en Espanol | D18: Doral Contemporary Art Museum, 3450 NW 83rd Avenue, Ste 216, Doral Florida, 33177 | E18: Gregory Saldamando | F18: First Stop Legal | G18: Legal & Accounting > Legal & Accounting (Other) | H18: (786) 498-2210 | I18: =DATE(2025, 11, 3) -> 45964 | J18: Gabriel Khalil | K18: Jonathan Oliveira
C19: BNI Doral en Espanol | D19: Doral Contemporary Art Museum, 3450 NW 83rd Avenue, Ste 216, Doral Florida, 33178 | E19: Jacqueline Gonzalez | F19: JP Morgan private bank | G19: Finance & Insurance > Wealth Management | H19: 305347008 | I19: =DATE(2025, 11, 3) -> 45964 | J19: Gabriel Khalil | K19: Jonathan Oliveira
C20: BNI Doral en Espanol | D20: Doral Contemporary Art Museum, 3450 NW 83rd Avenue, Ste 216, Doral Florida, 33179 | E20: Jimmy Arenas | F20: Mkaddesh Insurance & Financial Corp | G20: Finance & Insurance > Health Insurance | H20: 7867974310 | I20: =DATE(2025, 11, 3) -> 45964 | J20: Gabriel Khalil | K20: Jonathan Oliveira
C21: BNI Doral en Espanol | D21: Doral Contemporary Art Museum, 3450 NW 83rd Avenue, Ste 216, Doral Florida, 33180 | E21: Karla Lopez-Fernandez | F21: Law Office of Karla Lopez-Fernandez | G21: Legal & Accounting > Personal Injury Law | H21: (305)517-1116 | I21: =DATE(2025, 11, 3) -> 45964 | J21: Gabriel Khalil | K21: Jonathan Oliveira
C22: BNI Doral en Espanol | D22: Doral Contemporary Art Museum, 3450 NW 83rd Avenue, Ste 216, Doral Florida, 33181 | E22: LORRAINE PEREZ | F22: INTERCONTINENTAL LAW FIRM | G22: Legal & Accounting > Immigration Law | H22: +3054441272 | I22: =DATE(2025, 11, 3) -> 45964 | J22: Gabriel Khalil | K22: Jonathan Oliveira
C23: BNI Doral en Espanol | D23: Doral Contemporary Art Museum, 3450 NW 83rd Avenue, Ste 216, Doral Florida, 33182 | E23: LUZ SANCHEZ | F23: BUSINESS TIPS & ADVISORY SERVICES INC | G23: Legal & Accounting > Accounting Services | H23: 7865855929 | I23: =DATE(2025, 11, 3) -> 45964 | J23: Gabriel Khalil | K23: Jonathan Oliveira
C24: BNI Doral en Espanol | D24: Doral Contemporary Art Museum, 3450 NW 83rd Avenue, Ste 216, Doral Florida, 33183 | E24: Moises Benoliel | F24: Benoliel Consulting & Solutions LLC | G24: Real Estate Services > Real Estate Inspector | H24: 3058773711 | I24: =DATE(2025, 11, 3) -> 45964 | J24: Gabriel Khalil | K24: Jonathan Oliveira
C25: BNI Doral en Espanol | D25: Doral Contemporary Art Museum, 3450 NW 83rd Avenue, Ste 216, Doral Florida, 33184 | E25: Orestes Garcia | F25: Ayala Law | G25: Legal & Accounting > Litigation | H25: 7862104861 | I25: =DATE(2025, 11, 3) -> 45964 | J25: Gabriel Khalil | K25: Jonathan Oliveira
C26: BNI Doral en Espanol | D26: Doral Contemporary Art Museum, 3450 NW 83rd Avenue, Ste 216, Doral Florida, 33185 | E26: Ramón Rodríguez | F26: Avanti Way Realty | G26: Real Estate Services > Residential Real Estate Agent | H26: +13054975435 | I26: =DATE(2025, 11, 3) -> 45964 | J26: Gabriel Khalil | K26: Jonathan Oliveira
C27: BNI Doral en Espanol | D27: Doral Contemporary Art Museum, 3450 NW 83rd Avenue, Ste 216, Doral Florida, 33186 | E27: Ronald Dell'acqua | F27: Fotografo | G27: Advertising & Marketing > Photographer | H27: 7862141480 | I27: =DATE(2025, 11, 3) -> 45964 | J27: Gabriel Khalil | K27: Jonathan Oliveira
C28: BNI Doral en Espanol | D28: Doral Contemporary Art Museum, 3450 NW 83rd Avenue, Ste 216, Doral Florida, 33187 | E28: Susana Grant | F28: Folio Title LLC | G28: Real Estate Services > Title Services | H28: 3057789684 | I28: =DATE(2025, 11, 3) -> 45964 | J28: Gabriel Khalil | K28: Jonathan Oliveira
C29: BNI Doral Excellences | D29: Waterford District, 6505 Waterford District Drive, Ste 108 Miami, Florida, 33126 | E29: Alberto Diaz | F29: MOR Lending | G29: Finance & Insurance > Residential Mortgages | H29: 7862394998 | I29: =DATE(2025, 11, 3) -> 45964 | J29: Gabriel Khalil | K29: Jonathan Oliveira
C30: BNI Doral Excellences | D30: Waterford District, 6505 Waterford District Drive, Ste 108 Miami, Florida, 33127 | E30: Ana Paredes | F30: ABP Accounting | G30: Legal & Accounting > Accounting Services | H30: 786-477-3028 | I30: =DATE(2025, 11, 3) -> 45964 | J30: Gabriel Khalil | K30: Jonathan Oliveira
C31: BNI Doral Excellences | D31: Waterford District, 6505 Waterford District Drive, Ste 108 Miami, Florida, 33128 | E31: Bibiana Martorell | F31: Estrella insurance | G31: Finance & Insurance > Property & Casualty Insurance | H31: 3056449301 | I31: =DATE(2025, 11, 3) -> 45964 | J31: Gabriel Khalil | K31: Jonathan Oliveira
C32: BNI Doral Excellences | D32: Waterford District, 6505 Waterford District Drive, Ste 108 Miami, Florida, 33129 | E32: Christopher Rivas | F32: T&S Impact Windows & Doors | G32: Construction > Windows & Doors | H32: 786-223-5502 | I32: =DATE(2025, 11, 3) -> 45964 | J32: Gabriel Khalil | K32: Jonathan Oliveira
C33: BNI Doral Excellences | D33: Waterford District, 6505 Waterford District Drive, Ste 108 Miami, Florida, 33130 | E33: Gabriel Quiroga | F33: Compass | G33: Real Estate Services > Residential Real Estate Agent | H33: +17862345780 | I33: =DATE(2025, 11, 3) -> 45964 | J33: Gabriel Khalil | K33: Jonathan Oliveira
C34: BNI Doral Excellences | D34: Waterford District, 6505 Waterford District Drive, Ste 108 Miami, Florida, 33131 | E34: Jesus Lara | F34: New York Life | G34: Finance & Insurance > Life and Disability Insurance | H34: 3057932567 | I34: =DATE(2025, 11, 3) -> 45964 | J34: Gabriel Khalil | K34: Jonathan Oliveira | L34: No show
C35: BNI Doral Excellences | D35: Waterford District, 6505 Waterford District Drive, Ste 108 Miami, Florida, 33132 | E35: Jose Garcia | F35: UBS Financial Services | G35: Finance & Insurance > Financial Advisor | H35: 305-733-3771 | I35: =DATE(2025, 11, 3) -> 45964 | J35: Gabriel Khalil | K35: Jonathan Oliveira
C36: BNI Doral Excellences | D36: Waterford District, 6505 Waterford District Drive, Ste 108 Miami, Florida, 33133 | E36: Kevin Spencer | F36: Rod Plus Technology LLC | G36: Computer & Programming > IT & Networks | H36: 3058593035 | I36: =DATE(2025, 11, 3) -> 45964 | J36: Gabriel Khalil | K36: Jonathan Oliveira | L36: No show
C37: BNI Doral Excellences | D37: Waterford District, 6505 Waterford District Drive, Ste 108 Miami, Florida, 33134 | E37: Ricardo Rodriguez | F37: Rodriguez Law PL | G37: Legal & Accounting > Litigation | H37: 305-262-8226 | I37: =DATE(2025, 11, 3) -> 45964 | J37: Gabriel Khalil | K37: Jonathan Oliveira
C38: BNI Doral Excellences | D38: Waterford District, 6505 Waterford District Drive, Ste 108 Miami, Florida, 33135 | E38: Stephen Guerrero | F38: Guerrero Law Group PLLC | G38: Legal & Accounting > Estate Planning Law | H38: (305) 488-6250 | I38: =DATE(2025, 11, 3) -> 45964 | J38: Gabriel Khalil | K38: Jonathan Oliveira
C39: BNI Doral Excellences | D39: Waterford District, 6505 Waterford District Drive, Ste 108 Miami, Florida, 33136 | E39: Sunem Herrera | F39: The Herrera Insurance Group | G39: Finance & Insurance > Commercial Insurance | H39: 305-264-0177 | I39: =DATE(2025, 11, 3) -> 45964 | J39: Gabriel Khalil | K39: Jonathan Oliveira
C40: BNI Doral Excellences | D40: Waterford District, 6505 Waterford District Drive, Ste 108 Miami, Florida, 33137 | E40: Tongelah Webster | F40: City Permit | G40: Construction > Construction (Other) | H40: 305-908-1142 | I40: =DATE(2025, 11, 3) -> 45964 | J40: Gabriel Khalil | K40: Jonathan Oliveira
C41: BNI Lux Connect | D41: Industrious Lincoln Road, 350 Lincoln Rd 3rd Floor, Miami Beach, Florida, 33139 | E41: Agustina Valdovinos | F41: N/A | G41: Real Estate Services > Title Services | H41: 9542929759 | I41: =DATE(2025, 11, 3) -> 45964 | J41: Gabriel Khalil | K41: Jonathan Oliveira
C42: BNI Lux Connect | D42: Industrious Lincoln Road, 350 Lincoln Rd 3rd Floor, Miami Beach, Florida, 33140 | E42: Alexandra Almanza | F42: Socially Mavs | G42: Advertising & Marketing > Advertising & Marketing (Other) | H42: 786) 867-8861 | I42: =DATE(2025, 11, 3) -> 45964 | J42: Gabriel Khalil | K42: Jonathan Oliveira
C43: BNI Lux Connect | D43: Industrious Lincoln Road, 350 Lincoln Rd 3rd Floor, Miami Beach, Florida, 33141 | E43: Attila Yildiz | F43: Coldwell Banker | G43: Real Estate Services > Residential Real Estate Agent | H43: 786-333-3727 | I43: =DATE(2025, 11, 3) -> 45964 | J43: Gabriel Khalil | K43: Jonathan Oliveira
C44: BNI Lux Connect | D44: Industrious Lincoln Road, 350 Lincoln Rd 3rd Floor, Miami Beach, Florida, 33142 | E44: Bernard Cohen | F44: UBS | G44: Finance & Insurance > Financial Advisor | H44: 212-626-8712 | I44: =DATE(2025, 11, 3) -> 45964 | J44: Gabriel Khalil | K44: Jonathan Oliveira
C45: BNI Lux Connect | D45: Industrious Lincoln Road, 350 Lincoln Rd 3rd Floor, Miami Beach, Florida, 33143 | E45: Chris Cooney | F45: Affinity Management Services | G45: Real Estate Services > Property Management | H45: 305-619-5663 | I45: =DATE(2025, 11, 3) -> 45964 | J45: Gabriel Khalil | K45: Jonathan Oliveira
...
